<?xml version="1.0"?>
<robot name="green_crane">




  <material name="green">
    <color rgba="0 0.8 0 1"/>
  </material>





   
<link name="world_link"></link>


  <link name="base_link">
    <visual>
      <origin rpy="0 0 0" xyz="0 0 0.57207"/>
      <geometry>
         <mesh filename="package://crane_visualization/meshes/frame_URDF.STL"/> 
      </geometry>
      <material name="green"/>
    </visual>
  </link>


 <link name="crane_boom">
    <visual> 
      <origin rpy="0 0 0" xyz="3.10836 0 0.06343"/>
      <geometry>
        <mesh filename="package://crane_visualization/meshes/boom_URDF.STL"/>
      </geometry>
      <material name="green"/>
    </visual>
  </link>
  
    <link name="tooltip">
    <visual>
      <origin rpy="0 0 0" xyz="3.68 0.1 0.15"/>
      <geometry>
        <box size="0 0 0"/>
      </geometry>
      <material name="green"/>
    </visual>
  </link>






  <joint name="world_joint" type="fixed">
    <parent link="world_link"/>
    <child link="base_link"/>
    <origin xyz="0 0 0.956"/>
   </joint>
   
 
 <joint name="base_to_crane_boom" type="revolute">
    <axis xyz="0 1 0"/>
    <limit effort="1000.0" lower="0.3267" upper="-0.6948" velocity="0.5"/>
    <origin rpy="0 0 0"  xyz="-0.56876 0 1.752"/>
    <parent link="base_link"/>
    <child link="crane_boom"/>
  </joint>
  
  
  
  <joint name="craneboom_to_tooltip" type="fixed">
    <parent link="crane_boom"/>
    <child link="tooltip"/>
    <origin xyz="3.68 0 0"/>
   </joint>
  
 

</robot>
