<?xml version="1.0"?>
<robot name="simple_green_crane">

  <material name="green">
    <color rgba="0 0.4 0 1"/>
  </material>

  <link name="base_link">
    <visual>
      <geometry>
        <box size="0.3 0.65 1.912"/>
      </geometry>
      <material name="green"/>
      <origin xyz="0 0 0.956"/>
    </visual>
  </link>

  <link name="crane_boom">
    <visual>
      <geometry>
        <box size="3.68 0.1 0.15"/>
      </geometry>
      <material name="green"/>
      <origin rpy="0 0 0" xyz="1.76 0 0"/>
    </visual>
  </link>

  <joint name="base_to_crane_boom" type="revolute">
    <axis xyz="0 1 0"/>
    <limit effort="1000.0" lower="0.3267" upper="-0.6948" velocity="0.5"/>
    <origin rpy="0 0 0"  xyz="0 0 1.752"/>
    <parent link="base_link"/>
    <child link="crane_boom"/>
  </joint>

  <link name="toolpoint">
    <visual>
      <geometry>
        <box size="0 0 0"/>
      </geometry>
      <material name="green"/>
      <origin xyz="0 0 0.956"/>
    </visual>
  </link>

  <joint name="crane_boom_to_toolpoint" type="fixed">
    <origin rpy="0 0 0"  xyz="3.6 0 0"/>
    <parent link="crane_boom"/>
    <child link="toolpoint"/>
  </joint>

</robot>
